<?xml version="1.0"?>
<robot xmlns:xacro="http://www.ros.org/wiki/xacro">
  <link name="barrett_base_link">
    <inertial>
      <origin xyz="0 0 1" rpy="0 0 0"/>
      <mass value="0.0001"/>
      <inertia 
        ixx="1.0" ixy="0.0" ixz="0.0" 
        iyy="1.0" iyz="0.0" 
        izz="1.0"/>
    </inertial>
    <visual>
      <origin
        xyz="0 0 0"
        rpy="0 0 0" />
      <geometry>
        <mesh filename="package://barrett_hand_description/meshes/base_link.STL" />
      </geometry>
      <material name="">
        <color rgba="0.752941176470588 0.752941176470588 0.752941176470588 1" />
      </material>
    </visual>
    <collision>
      <origin xyz="0 0 0" rpy="0 0 0" />
      <geometry>
        <mesh filename="package://barrett_hand_description/meshes/base_link.STL" />
      </geometry>
    </collision>
  </link>
  <link name="finger_1_prox_link">
    <inertial>
      <origin xyz="0 0 1" rpy="0 0 0"/>
      <mass value="0.0001"/>
      <inertia 
        ixx="1.0" ixy="0.0" ixz="0.0" 
        iyy="1.0" iyz="0.0" 
        izz="1.0"/>
    </inertial>
    <visual>
      <origin
        xyz="0 0 0"
        rpy="0 0 0" />
      <geometry>
        <mesh
          filename="package://barrett_hand_description/meshes/finger_1_prox_link.STL" />
      </geometry>
      <material
        name="">
        <color
          rgba="0.752941176470588 0.752941176470588 0.752941176470588 1" />
      </material>
    </visual>
    <collision>
      <origin
        xyz="0 0 0"
        rpy="0 0 0" />
      <geometry>
        <mesh
          filename="package://barrett_hand_description/meshes/finger_1_prox_link.STL" />
      </geometry>
    </collision>
  </link>
  <joint
    name="finger_1_prox_joint"
    type="revolute">
    <origin
      xyz="0.025 0 0.0415"
      rpy="0 2.7051E-17 -1.5708" />
    <parent
      link="barrett_base_link" />
    <child
      link="finger_1_prox_link" />
    <axis
      xyz="0 0 -1" />
    <limit
      lower="0.0"
      upper="3.141"
      effort="0"
      velocity="0.01" />
   <dynamics damping="0.0" friction="0.0" />
  </joint>
  <link
    name="finger_1_med_link">
    <inertial>
      <origin xyz="0 0 1" rpy="0 0 0"/>
      <mass value="0.0001"/>
      <inertia 
        ixx="1.0" ixy="0.0" ixz="0.0" 
        iyy="1.0" iyz="0.0" 
        izz="1.0"/>
    </inertial>
    <visual>
      <origin
        xyz="0 0 0"
        rpy="3.14159265359 0 0" />
      <geometry>
        <mesh
          filename="package://barrett_hand_description/meshes/finger_1_med_link.STL" />
      </geometry>
      <material
        name="">
        <color
          rgba="0.752941176470588 0.752941176470588 0.752941176470588 1" />
      </material>
    </visual>
    <collision>
      <origin
        xyz="0 0 0"
        rpy="3.14159265359 0 0" />
      <geometry>
        <mesh
          filename="package://barrett_hand_description/meshes/finger_1_med_link.STL" />
      </geometry>
    </collision>
  </link>
  <joint
    name="finger_1_med_joint"
    type="revolute">
    <origin
      xyz="-0.05 0 0.0339"
      rpy="-1.5708 -8.8281E-17 0" />
    <parent
      link="finger_1_prox_link" />
    <child
      link="finger_1_med_link" />
    <axis
      xyz="0 0 1" />
    <limit
      lower="0"
      upper="2.44"
      effort="0"
      velocity="0.01" />
   <dynamics damping="0.0" friction="0.0" />
  </joint>
  <link
    name="finger_1_dist_link">
    <inertial>
      <origin xyz="0 0 1" rpy="0 0 0"/>
      <mass value="0.0001"/>
      <inertia 
        ixx="1.0" ixy="0.0" ixz="0.0" 
        iyy="1.0" iyz="0.0" 
        izz="1.0"/>
    </inertial>
    <visual>
      <origin
        xyz="0 0 0"
        rpy="3.14159265359 0 -0.73" />
      <geometry>
        <mesh
          filename="package://barrett_hand_description/meshes/finger_1_dist_link.STL" />
      </geometry>
      <material
        name="">
        <color
          rgba="0.898039215686275 0.917647058823529 0.929411764705882 1" />
      </material>
    </visual>
    <collision>
      <origin
        xyz="0 0 0"
        rpy="3.14159265359 0 -0.73" />
      <geometry>
        <mesh
          filename="package://barrett_hand_description/meshes/finger_1_dist_link.STL" />
      </geometry>
    </collision>
  </link>
  <joint
    name="finger_1_dist_joint"
    type="revolute"> <!--original is revolute-->
    <origin
      xyz="-0.069936 -0.003 0"
      rpy="1.6787E-18 -3.6382E-15 -6.1073E-33" />
    <parent
      link="finger_1_med_link" />
    <child
      link="finger_1_dist_link" />
    <axis
      xyz="0 0 1" />
    <limit
      lower="0.6"
      upper="1.57"
      effort="0"
      velocity="0.01" />
   <dynamics damping="0.0" friction="0.0" />
  </joint>
  <link
    name="finger_2_prox_link">
    <inertial>
      <origin xyz="0 0 1" rpy="0 0 0"/>
      <mass value="0.0001"/>
      <inertia 
        ixx="1.0" ixy="0.0" ixz="0.0" 
        iyy="1.0" iyz="0.0" 
        izz="1.0"/>
    </inertial>
    <visual>
      <origin
        xyz="0 0 0"
        rpy="0 0 0" />
      <geometry>
        <mesh
          filename="package://barrett_hand_description/meshes/finger_2_prox_link.STL" />
      </geometry>
      <material
        name="">
        <color
          rgba="0.752941176470588 0.752941176470588 0.752941176470588 1" />
      </material>
    </visual>
    <collision>
      <origin
        xyz="0 0 0"
        rpy="0 0 0" />
      <geometry>
        <mesh
          filename="package://barrett_hand_description/meshes/finger_2_prox_link.STL" />
      </geometry>
    </collision>
  </link>
  <joint
    name="finger_2_prox_joint"
    type="revolute">
    <origin
      xyz="-0.025 0 0.0415"
      rpy="0 2.7051E-17 -1.5708" />
    <parent
      link="barrett_base_link" />
    <child
      link="finger_2_prox_link" />
    <axis
      xyz="0 0 1" />
    <limit
      lower="0"
      upper="3.141"
      effort="0"
      velocity="0.01" />
   <dynamics damping="0.0" friction="0.0" />
  </joint>
  <link
    name="finger_2_med_link">
    <inertial>
      <origin xyz="0 0 1" rpy="0 0 0"/>
      <mass value="0.0001"/>
      <inertia 
        ixx="1.0" ixy="0.0" ixz="0.0" 
        iyy="1.0" iyz="0.0" 
        izz="1.0"/>
    </inertial>
    <visual>
      <origin
        xyz="0 0 0"
        rpy="3.14159265359 0 0" />
      <geometry>
        <mesh
          filename="package://barrett_hand_description/meshes/finger_2_med_link.STL" />
      </geometry>
      <material
        name="">
        <color
          rgba="0.752941176470588 0.752941176470588 0.752941176470588 1" />
      </material>
    </visual>
    <collision>
      <origin
        xyz="0 0 0"
        rpy="3.14159265359 0 0" />
      <geometry>
        <mesh
          filename="package://barrett_hand_description/meshes/finger_2_med_link.STL" />
      </geometry>
    </collision>
  </link>
  <joint
    name="finger_2_med_joint"
    type="revolute">
    <origin
      xyz="-0.05 0 0.0339"
      rpy="-1.5708 -8.8281E-17 0" />
    <parent
      link="finger_2_prox_link" />
    <child
      link="finger_2_med_link" />
    <axis
      xyz="0 0 1" />
    <limit
      lower="0.0"
      upper="2.44"
      effort="0"
      velocity="0.01" />
   <dynamics damping="0.0" friction="0.0" />
  </joint>
  <link
    name="finger_2_dist_link">
    <inertial>
      <origin xyz="0 0 1" rpy="0 0 0"/>
      <mass value="0.0001"/>
      <inertia 
        ixx="1.0" ixy="0.0" ixz="0.0" 
        iyy="1.0" iyz="0.0" 
        izz="1.0"/>
    </inertial>
    <visual>
      <origin
        xyz="0 0 0"
        rpy="3.14159265359 0 -0.73" />
      <geometry>
        <mesh
          filename="package://barrett_hand_description/meshes/finger_2_dist_link.STL" />
      </geometry>
      <material
        name="">
        <color
          rgba="0.898039215686275 0.917647058823529 0.929411764705882 1" />
      </material>
    </visual>
    <collision>
      <origin
        xyz="0 0 0"
        rpy="3.14159265359 0 -0.73" />
      <geometry>
        <mesh
          filename="package://barrett_hand_description/meshes/finger_2_dist_link.STL" />
      </geometry>
    </collision>
  </link>
  <joint
    name="finger_2_dist_joint"
    type="revolute"> <!--original is revolute-->
    <origin
      xyz="-0.069917 -0.0034087 0"
      rpy="-3.1382E-17 -2.3229E-16 0" />
    <parent
      link="finger_2_med_link" />
    <child
      link="finger_2_dist_link" />
    <axis
      xyz="0 0 1" />
    <limit
      lower="0.6"
      upper="1.57"
      effort="0"
      velocity="0.01" />
   <dynamics damping="0.0" friction="0.0" />
  </joint>
  <link
    name="finger_3_med_link">
    <inertial>
      <origin xyz="0 0 1" rpy="0 0 0"/>
      <mass value="0.0001"/>
      <inertia 
        ixx="1.0" ixy="0.0" ixz="0.0" 
        iyy="1.0" iyz="0.0" 
        izz="1.0"/>
    </inertial>
    <visual>
      <origin
        xyz="0 0 0"
        rpy="3.14159265359 0 0" />
      <geometry>
        <mesh
          filename="package://barrett_hand_description/meshes/finger_3_med_link.STL" />
      </geometry>
      <material
        name="">
        <color
          rgba="0.752941176470588 0.752941176470588 0.752941176470588 1" />
      </material>
    </visual>
    <collision>
      <origin
        xyz="0 0 0"
        rpy="3.14159265359 0 0" />
      <geometry>
        <mesh
          filename="package://barrett_hand_description/meshes/finger_3_med_link.STL" />
      </geometry>
    </collision>
  </link>
  <joint
    name="finger_3_med_joint"
    type="revolute">
    <origin
      xyz="0 -0.05 0.0754"
      rpy="-1.5708 6.123E-17 1.5708" />
    <parent
      link="barrett_base_link" />
    <child
      link="finger_3_med_link" />
    <axis
      xyz="0 0 1" />
    <limit
      lower="0.0"
      upper="2.44"
      effort="0"
      velocity="0.01" />
   <dynamics damping="0.0" friction="0.0" />
  </joint>
  <link
    name="finger_3_dist_link">
    <inertial>
      <origin xyz="0 0 1" rpy="0 0 0"/>
      <mass value="0.0001"/>
      <inertia 
        ixx="1.0" ixy="0.0" ixz="0.0" 
        iyy="1.0" iyz="0.0" 
        izz="1.0"/>
    </inertial>
    <visual>
      <origin
        xyz="0 0 0"
        rpy="3.14159265359 0 -0.73" />
      <geometry>
        <mesh
          filename="package://barrett_hand_description/meshes/finger_3_dist_link.STL" />
      </geometry>
      <material
        name="">
        <color
          rgba="0.898039215686275 0.917647058823529 0.929411764705882 1" />
      </material>
    </visual>
    <collision>
      <origin
        xyz="0 0 0"
        rpy="3.14159265359 0 -0.73" />
      <geometry>
        <mesh
          filename="package://barrett_hand_description/meshes/finger_3_dist_link.STL" />
      </geometry>
    </collision>
  </link>
  <joint
    name="finger_3_dist_joint"
    type="revolute"> <!--original is revolute-->
    <origin
      xyz="-0.069936 -0.003 0"
      rpy="6.0427E-17 -6.7283E-18 -4.0657E-34" />
    <parent
      link="finger_3_med_link" />
    <child
      link="finger_3_dist_link" />
    <axis
      xyz="0 0 1" />
    <limit
      lower="0.6"
      upper="1.57"
      effort="0"
      velocity="0" />
   <dynamics damping="0.0" friction="0.0" />
  </joint>



  <transmission name="tran11">
    <type>transmission_interface/SimpleTransmission</type>
    <joint name="finger_1_med_joint"/>
    <actuator name="motor11">
      <hardwareInterface>EffortJointInterface</hardwareInterface>
      <mechanicalReduction>1</mechanicalReduction>
    </actuator>
  </transmission>

  <transmission name="tran12">
    <type>transmission_interface/SimpleTransmission</type>
    <joint name="finger_1_dist_joint"/>
    <actuator name="motor12">
      <hardwareInterface>EffortJointInterface</hardwareInterface>
      <mechanicalReduction>10</mechanicalReduction>
    </actuator>
  </transmission>

  <transmission name="tran13">
    <type>transmission_interface/SimpleTransmission</type>
    <joint name="finger_2_med_joint"/>
    <actuator name="motor13">
      <hardwareInterface>EffortJointInterface</hardwareInterface>
      <mechanicalReduction>1</mechanicalReduction>
    </actuator>
  </transmission>

  <transmission name="tran14">
    <type>transmission_interface/SimpleTransmission</type>
    <joint name="finger_2_dist_joint"/>
    <actuator name="motor14">
      <hardwareInterface>EffortJointInterface</hardwareInterface>
      <mechanicalReduction>10</mechanicalReduction>
    </actuator>
  </transmission>

  <transmission name="tran15">
    <type>transmission_interface/SimpleTransmission</type>
    <joint name="finger_3_med_joint"/>
    <actuator name="motor15">
      <hardwareInterface>EffortJointInterface</hardwareInterface>
      <mechanicalReduction>1</mechanicalReduction>
    </actuator>
  </transmission>

  <transmission name="tran16">
    <type>transmission_interface/SimpleTransmission</type>
    <joint name="finger_3_dist_joint"/>
    <actuator name="motor16">
      <hardwareInterface>EffortJointInterface</hardwareInterface>
      <mechanicalReduction>1</mechanicalReduction>
    </actuator>
  </transmission>

  <transmission name="tran17">
    <type>transmission_interface/SimpleTransmission</type>
    <joint name="finger_1_prox_joint"/>
    <actuator name="motor17">
      <hardwareInterface>EffortJointInterface</hardwareInterface>
      <mechanicalReduction>1</mechanicalReduction>
    </actuator>
  </transmission>

  <transmission name="tran18">
    <type>transmission_interface/SimpleTransmission</type>
    <joint name="finger_2_prox_joint"/>
    <actuator name="motor18">
      <hardwareInterface>EffortJointInterface</hardwareInterface>
      <mechanicalReduction>1</mechanicalReduction>
    </actuator>
  </transmission>

</robot>
